<mujoco>
	<option gravity='0 0 0'/>
	<worldbody>
        <light diffuse=".5 .5 .5" pos="0 0 3" dir="0 0 -1"/>
		<geom type="plane" size="2 2 0.1" rgba="1 1 1 1"/>
		<body pos="0 0 0.1" euler='0 90 0'>
			<joint type="hinge" axis='-1 0 0' pos='0 0 -0.5'/>
			<geom type="cylinder" size="0.05 0.5" rgba="0.8 0 0.3 0.7"/>
			<body pos="0 0 1" euler='0 0 0'>
				<joint type="hinge" axis='-1 0 0' pos='0 0 -0.5'/>
				<geom type="cylinder" size="0.05 0.5" rgba="0.1 0.1 0.8 0.7"/>
			</body>
		</body>
	</worldbody>
</mujoco>
